# 10.3 new演算子の例外処理
## 10.3.1 std:bad_alloc例外
new演算子は動的メモリを確保するために使われる演算子ですが、必要なメモリを確保できなかった場合std::bad_alloc例外が投げられます。
この例外は標準ライブラリで規定されているstd::exception例外から発生した例外の1つで、<new>ヘッダーにおいて定義されています。

new演算子が割り当てに失敗した場合、それは動的メモリを確保できないということを意味します。そのため、例外ハンドラーの中でも動的メモリを使用するような処理はほとんど不可能だと考えられます。一般的にこの種の例外は、受け取ったからといって何か手立てがあるわけではないので、そもそもcatchすらしない(std::terminate()関数で終了させるしかない) 場合がほとんどです。

catch節では例外オブジェクトを参照を使って捕まえています。一般に例外オブジェクトは、例外が投げられた段階での様々な情報を持っていて、コピーをしてしまうとメモリの動的確保をしてしまうかもしれません。例外オブジェクトのコピーはcatch節に処理が完全に映る前になされるので、このタイミングでさらに例外が投げられると**ダブルフォルト**といって強制終了されます。
ダブルフォルトを防ぐためにも、例外オブジェクトがクラスの場合には参照で捕まえるようにしてください。
